<?xml version="1.0" encoding="utf-8"?>
<robot
  name="osp_teleop">
  <link
    name="base_link">
    <inertial>
      <origin
        xyz="-3.6902383357842E-06 0.00013530319817408 0.00484123488485292"
        rpy="0 0 0" />
      <mass
        value="15.8910309592199" />
      <inertia
        ixx="0.0613158294960087"
        ixy="1.80957428706809E-07"
        ixz="-6.43751720929848E-07"
        iyy="0.181610840835921"
        iyz="-4.36641485740763E-08"
        izz="0.181013569345721" />
    </inertial>
    <visual>
      <origin
        xyz="0 0 0"
        rpy="0 0 0" />
      <geometry>
        <mesh
          filename="package://osp_teleop/meshes/base_link.STL" />
      </geometry>
      <material
        name="">
        <color
          rgba="0.898039215686275 0.917647058823529 0.929411764705882 1" />
      </material>
    </visual>
    <collision>
      <origin
        xyz="0 0 0"
        rpy="0 0 0" />
      <geometry>
        <mesh
          filename="package://osp_teleop/meshes/base_link.STL" />
      </geometry>
    </collision>
  </link>
  <link
    name="flipper_1">
    <inertial>
      <origin
        xyz="-0.10322 3.5243E-05 0.040967"
        rpy="0 0 0" />
      <mass
        value="2.5754" />
      <inertia
        ixx="0.0025705"
        ixy="1.0125E-06"
        ixz="-7.2155E-08"
        iyy="0.012301"
        iyz="4.8037E-09"
        izz="0.014521" />
    </inertial>
    <visual>
      <origin
        xyz="0 0 0"
        rpy="0 0 0" />
      <geometry>
        <mesh
          filename="package://osp_teleop/meshes/flipper_1.STL" />
      </geometry>
      <material
        name="">
        <color
          rgba="0.75294 0.75294 0.75294 1" />
      </material>
    </visual>
    <collision>
      <origin
        xyz="0 0 0"
        rpy="0 0 0" />
      <geometry>
        <mesh
          filename="package://osp_teleop/meshes/flipper_1.STL" />
      </geometry>
    </collision>
  </link>
  <joint
    name="f1"
    type="continuous">
    <origin
      xyz="-0.208 -0.1691 0"
      rpy="1.5708 0.010345 0" />
    <parent
      link="base_link" />
    <child
      link="flipper_1" />
    <axis
      xyz="0 0 -1" />
  </joint>
  <link
    name="flipper_2">
    <inertial>
      <origin
        xyz="-0.10322 -3.5243E-05 -0.040967"
        rpy="0 0 0" />
      <mass
        value="2.5754" />
      <inertia
        ixx="0.0025705"
        ixy="-1.0125E-06"
        ixz="7.2155E-08"
        iyy="0.012301"
        iyz="4.8037E-09"
        izz="0.014521" />
    </inertial>
    <visual>
      <origin
        xyz="0 0 0"
        rpy="0 0 0" />
      <geometry>
        <mesh
          filename="package://osp_teleop/meshes/flipper_2.STL" />
      </geometry>
      <material
        name="">
        <color
          rgba="0.75294 0.75294 0.75294 1" />
      </material>
    </visual>
    <collision>
      <origin
        xyz="0 0 0"
        rpy="0 0 0" />
      <geometry>
        <mesh
          filename="package://osp_teleop/meshes/flipper_2.STL" />
      </geometry>
    </collision>
  </link>
  <joint
    name="f2"
    type="continuous">
    <origin
      xyz="-0.208 0.1691 0"
      rpy="1.5708 0.032193 0" />
    <parent
      link="base_link" />
    <child
      link="flipper_2" />
    <axis
      xyz="0 0 1" />
  </joint>
  <link
    name="flipper_3">
    <inertial>
      <origin
        xyz="0.10322 3.5243E-05 -0.040967"
        rpy="0 0 0" />
      <mass
        value="2.5754" />
      <inertia
        ixx="0.0025705"
        ixy="-1.0125E-06"
        ixz="-7.2155E-08"
        iyy="0.012301"
        iyz="-4.8037E-09"
        izz="0.014521" />
    </inertial>
    <visual>
      <origin
        xyz="0 0 0"
        rpy="0 0 0" />
      <geometry>
        <mesh
          filename="package://osp_teleop/meshes/flipper_3.STL" />
      </geometry>
      <material
        name="">
        <color
          rgba="0.75294 0.75294 0.75294 1" />
      </material>
    </visual>
    <collision>
      <origin
        xyz="0 0 0"
        rpy="0 0 0" />
      <geometry>
        <mesh
          filename="package://osp_teleop/meshes/flipper_3.STL" />
      </geometry>
    </collision>
  </link>
  <joint
    name="f3"
    type="continuous">
    <origin
      xyz="0.208 0.1691 0"
      rpy="1.5708 -0.010345 0" />
    <parent
      link="base_link" />
    <child
      link="flipper_3" />
    <axis
      xyz="0 0 1" />
  </joint>
  <link
    name="flipper_4">
    <inertial>
      <origin
        xyz="0 0 0"
        rpy="0 0 0" />
      <mass
        value="0" />
      <inertia
        ixx="0"
        ixy="0"
        ixz="0"
        iyy="0"
        iyz="0"
        izz="0" />
    </inertial>
    <visual>
      <origin
        xyz="0 0 0"
        rpy="0 0 0" />
      <geometry>
        <mesh
          filename="package://osp_teleop/meshes/flipper_4.STL" />
      </geometry>
      <material
        name="">
        <color
          rgba="1 1 1 1" />
      </material>
    </visual>
    <collision>
      <origin
        xyz="0 0 0"
        rpy="0 0 0" />
      <geometry>
        <mesh
          filename="package://osp_teleop/meshes/flipper_4.STL" />
      </geometry>
    </collision>
  </link>
  <joint
    name="f4"
    type="continuous">
    <origin
      xyz="0.207999999999999 -0.169099999999999 0"
      rpy="1.5707963267949 -0.0103448863749507 3.14159265358979" />
    <parent
      link="base_link" />
    <child
      link="flipper_4" />
    <axis
      xyz="0 0 1" />
  </joint>
</robot>